2022-12-09 20:24:47,591 INFO    MainThread:3275 [internal.py:wandb_internal():92] W&B internal server running at pid: 3275, started at: 2022-12-09 20:24:47.590955
2022-12-09 20:24:47,593 INFO    WriterThread:3275 [datastore.py:open_for_write():77] open: /Users/livionmbp/Documents/GitHub/Sources/3DGridWorld/wandb/run-20221209_202446-po5cuaz3/run-po5cuaz3.wandb
2022-12-09 20:24:47,595 DEBUG   SenderThread:3275 [sender.py:send():235] send: header
2022-12-09 20:24:47,595 DEBUG   SenderThread:3275 [sender.py:send():235] send: run
2022-12-09 20:24:48,267 INFO    SenderThread:3275 [dir_watcher.py:__init__():169] watching files in: /Users/livionmbp/Documents/GitHub/Sources/3DGridWorld/wandb/run-20221209_202446-po5cuaz3/files
2022-12-09 20:24:48,267 INFO    SenderThread:3275 [sender.py:_start_run_threads():812] run started: po5cuaz3 with start time 1670588686
2022-12-09 20:24:48,268 DEBUG   SenderThread:3275 [sender.py:send():235] send: summary
2022-12-09 20:24:48,269 INFO    SenderThread:3275 [sender.py:_save_file():947] saving file wandb-summary.json with policy end
2022-12-09 20:24:48,270 DEBUG   HandlerThread:3275 [handler.py:handle_request():141] handle_request: check_version
2022-12-09 20:24:48,270 DEBUG   SenderThread:3275 [sender.py:send_request():249] send_request: check_version
2022-12-09 20:24:49,272 INFO    Thread-7  :3275 [dir_watcher.py:_on_file_created():217] file/dir created: /Users/livionmbp/Documents/GitHub/Sources/3DGridWorld/wandb/run-20221209_202446-po5cuaz3/files/wandb-summary.json
2022-12-09 20:24:51,187 DEBUG   HandlerThread:3275 [handler.py:handle_request():141] handle_request: run_start
2022-12-09 20:24:51,189 DEBUG   HandlerThread:3275 [meta.py:__init__():37] meta init
2022-12-09 20:24:51,189 DEBUG   HandlerThread:3275 [meta.py:__init__():51] meta init done
2022-12-09 20:24:51,189 DEBUG   HandlerThread:3275 [meta.py:probe():211] probe
2022-12-09 20:24:51,198 DEBUG   HandlerThread:3275 [meta.py:_setup_git():201] setup git
2022-12-09 20:24:51,243 DEBUG   HandlerThread:3275 [meta.py:_setup_git():208] setup git done
2022-12-09 20:24:51,244 DEBUG   HandlerThread:3275 [meta.py:_save_code():89] save code
2022-12-09 20:24:51,267 DEBUG   HandlerThread:3275 [meta.py:_save_code():110] save code done
2022-12-09 20:24:51,267 DEBUG   HandlerThread:3275 [meta.py:_save_patches():127] save patches
2022-12-09 20:24:51,279 INFO    Thread-7  :3275 [dir_watcher.py:_on_file_created():217] file/dir created: /Users/livionmbp/Documents/GitHub/Sources/3DGridWorld/wandb/run-20221209_202446-po5cuaz3/files/code/PPOagent.py
2022-12-09 20:24:51,279 INFO    Thread-7  :3275 [dir_watcher.py:_on_file_created():217] file/dir created: /Users/livionmbp/Documents/GitHub/Sources/3DGridWorld/wandb/run-20221209_202446-po5cuaz3/files/code
2022-12-09 20:24:51,425 DEBUG   HandlerThread:3275 [meta.py:_save_patches():169] save patches done
2022-12-09 20:24:51,425 DEBUG   HandlerThread:3275 [meta.py:_save_pip():55] save pip
2022-12-09 20:24:51,426 DEBUG   HandlerThread:3275 [meta.py:_save_pip():69] save pip done
2022-12-09 20:24:51,426 DEBUG   HandlerThread:3275 [meta.py:_save_conda():76] save conda
2022-12-09 20:24:51,990 WARNING MainThread:3275 [internal.py:wandb_internal():155] Internal process interrupt: 1
2022-12-09 20:24:52,053 DEBUG   HandlerThread:3275 [meta.py:_save_conda():86] save conda done
2022-12-09 20:24:52,053 DEBUG   HandlerThread:3275 [meta.py:probe():249] probe done
2022-12-09 20:24:52,132 DEBUG   SenderThread:3275 [sender.py:send():235] send: files
2022-12-09 20:24:52,133 INFO    SenderThread:3275 [sender.py:_save_file():947] saving file wandb-metadata.json with policy now
2022-12-09 20:24:52,134 INFO    SenderThread:3275 [sender.py:_save_file():947] saving file code/PPOagent.py with policy now
2022-12-09 20:24:52,135 INFO    SenderThread:3275 [sender.py:_save_file():947] saving file diff.patch with policy now
2022-12-09 20:24:52,282 INFO    Thread-7  :3275 [dir_watcher.py:_on_file_created():217] file/dir created: /Users/livionmbp/Documents/GitHub/Sources/3DGridWorld/wandb/run-20221209_202446-po5cuaz3/files/diff.patch
2022-12-09 20:24:52,282 INFO    Thread-7  :3275 [dir_watcher.py:_on_file_created():217] file/dir created: /Users/livionmbp/Documents/GitHub/Sources/3DGridWorld/wandb/run-20221209_202446-po5cuaz3/files/wandb-metadata.json
2022-12-09 20:24:52,282 INFO    Thread-7  :3275 [dir_watcher.py:_on_file_created():217] file/dir created: /Users/livionmbp/Documents/GitHub/Sources/3DGridWorld/wandb/run-20221209_202446-po5cuaz3/files/conda-environment.yaml
2022-12-09 20:24:52,283 INFO    Thread-7  :3275 [dir_watcher.py:_on_file_created():217] file/dir created: /Users/livionmbp/Documents/GitHub/Sources/3DGridWorld/wandb/run-20221209_202446-po5cuaz3/files/requirements.txt
2022-12-09 20:24:52,944 INFO    Thread-12 :3275 [upload_job.py:push():117] Skipped uploading /var/folders/cs/3rd5xjms5qd5nj6fr2n86d380000gn/T/tmpph133j6vwandb/1lzbf70t-code/PPOagent.py
2022-12-09 20:24:53,161 ERROR   Thread-11 :3275 [internal_api.py:upload_file():1612] upload_file exception https://storage.googleapis.com/wandb-production.appspot.com/livion/GridWorld/po5cuaz3/wandb-metadata.json?Expires=1670675092&GoogleAccessId=wandb-production%40appspot.gserviceaccount.com&Signature=RW9BzYjp2XBDJrfR6htGS1TPEXJS4bOOFwQsSiOCWiaUHO1SMuy6VxNbSeF8yTeRwBZz6HY9L57daE5tooTpMkIIDFWNH3L7opzPgdWL03tumm3ymi%2FH2UX4%2FVO5%2BFD8N%2FsF7Wmwu3QOVqV%2FtnHKCeXa2gHcHT%2BZgSH17r%2FpOt4%2F1hrCcZEyKsBfIznC%2BNtYr0DNne47BxZCcEY5XqbepU5Sd7RR3gPbZussP5P4QDORBQ1ViboCq9mxZroWYsZbMWdsbnqIEo88YU477sWCbszeC7TLhAiqA6zPW5Ox%2ByyEf2Q71n5B4wcMsMpE8ObULUPJ7y2N3cXIhjz%2BTOPZ5Q%3D%3D: ('Connection aborted.', ConnectionResetError(54, 'Connection reset by peer'))
2022-12-09 20:24:53,161 ERROR   Thread-11 :3275 [internal_api.py:upload_file():1614] upload_file request headers: {'User-Agent': 'python-requests/2.27.1', 'Accept-Encoding': 'gzip, deflate', 'Accept': '*/*', 'Connection': 'keep-alive', 'Content-Length': '854'}
2022-12-09 20:24:53,161 ERROR   Thread-11 :3275 [internal_api.py:upload_file():1616] upload_file response body: 
2022-12-09 20:24:53,241 ERROR   Thread-13 :3275 [internal_api.py:upload_file():1612] upload_file exception https://storage.googleapis.com/wandb-production.appspot.com/livion/GridWorld/po5cuaz3/diff.patch?Expires=1670675093&GoogleAccessId=wandb-production%40appspot.gserviceaccount.com&Signature=ir3Y4stRUyjhJf3sq8Alayogz15KvLnBSX1%2BBiiq0QdxXqONLdU6NQMFuBLaMakTaVFUc0WBVpTmbYP65VEQ8We89gKeGdCRtpU9j6AtZZ1IRvT%2BlSgK2vNzFa4Jk81FkmNq419QS0nLBpAuGXarXYXlq2xVL3NbQqxD2CaQJVxSFlEJmC3B4AZmOfFOZv9%2FnQ0%2B%2FwRDxYsVPODEuDD6uHxsu0OkqROb25EjOT7Sy4A%2Bi8ecrShs3a6%2FxaGPWhyHS618XPaW8vtLHm5DrsjeW51wflvt6EYAcqBhmVv7oOnQr3tPLw1OoYvIYxI5sJY0wlqe18TcdcLcJUbLZCT0SQ%3D%3D: ('Connection aborted.', ConnectionResetError(54, 'Connection reset by peer'))
2022-12-09 20:24:53,241 ERROR   Thread-13 :3275 [internal_api.py:upload_file():1614] upload_file request headers: {'User-Agent': 'python-requests/2.27.1', 'Accept-Encoding': 'gzip, deflate', 'Accept': '*/*', 'Connection': 'keep-alive', 'Content-Length': '3348'}
2022-12-09 20:24:53,241 ERROR   Thread-13 :3275 [internal_api.py:upload_file():1616] upload_file response body: 
2022-12-09 20:24:53,286 INFO    Thread-7  :3275 [dir_watcher.py:_on_file_modified():230] file/dir modified: /Users/livionmbp/Documents/GitHub/Sources/3DGridWorld/wandb/run-20221209_202446-po5cuaz3/files/code
2022-12-09 20:24:54,289 INFO    Thread-7  :3275 [dir_watcher.py:_on_file_modified():230] file/dir modified: /Users/livionmbp/Documents/GitHub/Sources/3DGridWorld/wandb/run-20221209_202446-po5cuaz3/files/code
2022-12-09 20:24:54,586 ERROR   Thread-11 :3275 [internal_api.py:upload_file():1612] upload_file exception https://storage.googleapis.com/wandb-production.appspot.com/livion/GridWorld/po5cuaz3/wandb-metadata.json?Expires=1670675092&GoogleAccessId=wandb-production%40appspot.gserviceaccount.com&Signature=RW9BzYjp2XBDJrfR6htGS1TPEXJS4bOOFwQsSiOCWiaUHO1SMuy6VxNbSeF8yTeRwBZz6HY9L57daE5tooTpMkIIDFWNH3L7opzPgdWL03tumm3ymi%2FH2UX4%2FVO5%2BFD8N%2FsF7Wmwu3QOVqV%2FtnHKCeXa2gHcHT%2BZgSH17r%2FpOt4%2F1hrCcZEyKsBfIznC%2BNtYr0DNne47BxZCcEY5XqbepU5Sd7RR3gPbZussP5P4QDORBQ1ViboCq9mxZroWYsZbMWdsbnqIEo88YU477sWCbszeC7TLhAiqA6zPW5Ox%2ByyEf2Q71n5B4wcMsMpE8ObULUPJ7y2N3cXIhjz%2BTOPZ5Q%3D%3D: ('Connection aborted.', ConnectionResetError(54, 'Connection reset by peer'))
2022-12-09 20:24:54,587 ERROR   Thread-11 :3275 [internal_api.py:upload_file():1614] upload_file request headers: {'User-Agent': 'python-requests/2.27.1', 'Accept-Encoding': 'gzip, deflate', 'Accept': '*/*', 'Connection': 'keep-alive', 'Content-Length': '854'}
2022-12-09 20:24:54,587 ERROR   Thread-11 :3275 [internal_api.py:upload_file():1616] upload_file response body: 
2022-12-09 20:24:54,587 ERROR   Thread-11 :3275 [retry.py:__call__():126] Retry attempt failed:
Traceback (most recent call last):
  File "/Users/livionmbp/opt/anaconda3/envs/cleanrl/lib/python3.9/site-packages/urllib3/connectionpool.py", line 703, in urlopen
    httplib_response = self._make_request(
  File "/Users/livionmbp/opt/anaconda3/envs/cleanrl/lib/python3.9/site-packages/urllib3/connectionpool.py", line 386, in _make_request
    self._validate_conn(conn)
  File "/Users/livionmbp/opt/anaconda3/envs/cleanrl/lib/python3.9/site-packages/urllib3/connectionpool.py", line 1040, in _validate_conn
    conn.connect()
  File "/Users/livionmbp/opt/anaconda3/envs/cleanrl/lib/python3.9/site-packages/urllib3/connection.py", line 416, in connect
    self.sock = ssl_wrap_socket(
  File "/Users/livionmbp/opt/anaconda3/envs/cleanrl/lib/python3.9/site-packages/urllib3/util/ssl_.py", line 449, in ssl_wrap_socket
    ssl_sock = _ssl_wrap_socket_impl(
  File "/Users/livionmbp/opt/anaconda3/envs/cleanrl/lib/python3.9/site-packages/urllib3/util/ssl_.py", line 493, in _ssl_wrap_socket_impl
    return ssl_context.wrap_socket(sock, server_hostname=server_hostname)
  File "/Users/livionmbp/opt/anaconda3/envs/cleanrl/lib/python3.9/ssl.py", line 501, in wrap_socket
    return self.sslsocket_class._create(
  File "/Users/livionmbp/opt/anaconda3/envs/cleanrl/lib/python3.9/ssl.py", line 1041, in _create
    self.do_handshake()
  File "/Users/livionmbp/opt/anaconda3/envs/cleanrl/lib/python3.9/ssl.py", line 1310, in do_handshake
    self._sslobj.do_handshake()
ConnectionResetError: [Errno 54] Connection reset by peer

During handling of the above exception, another exception occurred:

Traceback (most recent call last):
  File "/Users/livionmbp/opt/anaconda3/envs/cleanrl/lib/python3.9/site-packages/requests/adapters.py", line 440, in send
    resp = conn.urlopen(
  File "/Users/livionmbp/opt/anaconda3/envs/cleanrl/lib/python3.9/site-packages/urllib3/connectionpool.py", line 785, in urlopen
    retries = retries.increment(
  File "/Users/livionmbp/opt/anaconda3/envs/cleanrl/lib/python3.9/site-packages/urllib3/util/retry.py", line 550, in increment
    raise six.reraise(type(error), error, _stacktrace)
  File "/Users/livionmbp/opt/anaconda3/envs/cleanrl/lib/python3.9/site-packages/urllib3/packages/six.py", line 769, in reraise
    raise value.with_traceback(tb)
  File "/Users/livionmbp/opt/anaconda3/envs/cleanrl/lib/python3.9/site-packages/urllib3/connectionpool.py", line 703, in urlopen
    httplib_response = self._make_request(
  File "/Users/livionmbp/opt/anaconda3/envs/cleanrl/lib/python3.9/site-packages/urllib3/connectionpool.py", line 386, in _make_request
    self._validate_conn(conn)
  File "/Users/livionmbp/opt/anaconda3/envs/cleanrl/lib/python3.9/site-packages/urllib3/connectionpool.py", line 1040, in _validate_conn
    conn.connect()
  File "/Users/livionmbp/opt/anaconda3/envs/cleanrl/lib/python3.9/site-packages/urllib3/connection.py", line 416, in connect
    self.sock = ssl_wrap_socket(
  File "/Users/livionmbp/opt/anaconda3/envs/cleanrl/lib/python3.9/site-packages/urllib3/util/ssl_.py", line 449, in ssl_wrap_socket
    ssl_sock = _ssl_wrap_socket_impl(
  File "/Users/livionmbp/opt/anaconda3/envs/cleanrl/lib/python3.9/site-packages/urllib3/util/ssl_.py", line 493, in _ssl_wrap_socket_impl
    return ssl_context.wrap_socket(sock, server_hostname=server_hostname)
  File "/Users/livionmbp/opt/anaconda3/envs/cleanrl/lib/python3.9/ssl.py", line 501, in wrap_socket
    return self.sslsocket_class._create(
  File "/Users/livionmbp/opt/anaconda3/envs/cleanrl/lib/python3.9/ssl.py", line 1041, in _create
    self.do_handshake()
  File "/Users/livionmbp/opt/anaconda3/envs/cleanrl/lib/python3.9/ssl.py", line 1310, in do_handshake
    self._sslobj.do_handshake()
urllib3.exceptions.ProtocolError: ('Connection aborted.', ConnectionResetError(54, 'Connection reset by peer'))

During handling of the above exception, another exception occurred:

Traceback (most recent call last):
  File "/Users/livionmbp/opt/anaconda3/envs/cleanrl/lib/python3.9/site-packages/wandb/sdk/internal/internal_api.py", line 1609, in upload_file
    response = requests.put(url, data=progress, headers=extra_headers)
  File "/Users/livionmbp/opt/anaconda3/envs/cleanrl/lib/python3.9/site-packages/requests/api.py", line 132, in put
    return request('put', url, data=data, **kwargs)
  File "/Users/livionmbp/opt/anaconda3/envs/cleanrl/lib/python3.9/site-packages/requests/api.py", line 61, in request
    return session.request(method=method, url=url, **kwargs)
  File "/Users/livionmbp/opt/anaconda3/envs/cleanrl/lib/python3.9/site-packages/requests/sessions.py", line 529, in request
    resp = self.send(prep, **send_kwargs)
  File "/Users/livionmbp/opt/anaconda3/envs/cleanrl/lib/python3.9/site-packages/requests/sessions.py", line 645, in send
    r = adapter.send(request, **kwargs)
  File "/Users/livionmbp/opt/anaconda3/envs/cleanrl/lib/python3.9/site-packages/requests/adapters.py", line 501, in send
    raise ConnectionError(err, request=request)
requests.exceptions.ConnectionError: ('Connection aborted.', ConnectionResetError(54, 'Connection reset by peer'))

During handling of the above exception, another exception occurred:

Traceback (most recent call last):
  File "/Users/livionmbp/opt/anaconda3/envs/cleanrl/lib/python3.9/site-packages/wandb/sdk/lib/retry.py", line 102, in __call__
    result = self._call_fn(*args, **kwargs)
  File "/Users/livionmbp/opt/anaconda3/envs/cleanrl/lib/python3.9/site-packages/wandb/sdk/internal/internal_api.py", line 1625, in upload_file
    six.reraise(type(e), e, sys.exc_info()[2])
  File "/Users/livionmbp/opt/anaconda3/envs/cleanrl/lib/python3.9/site-packages/six.py", line 718, in reraise
    raise value.with_traceback(tb)
  File "/Users/livionmbp/opt/anaconda3/envs/cleanrl/lib/python3.9/site-packages/wandb/sdk/internal/internal_api.py", line 1609, in upload_file
    response = requests.put(url, data=progress, headers=extra_headers)
  File "/Users/livionmbp/opt/anaconda3/envs/cleanrl/lib/python3.9/site-packages/requests/api.py", line 132, in put
    return request('put', url, data=data, **kwargs)
  File "/Users/livionmbp/opt/anaconda3/envs/cleanrl/lib/python3.9/site-packages/requests/api.py", line 61, in request
    return session.request(method=method, url=url, **kwargs)
  File "/Users/livionmbp/opt/anaconda3/envs/cleanrl/lib/python3.9/site-packages/requests/sessions.py", line 529, in request
    resp = self.send(prep, **send_kwargs)
  File "/Users/livionmbp/opt/anaconda3/envs/cleanrl/lib/python3.9/site-packages/requests/sessions.py", line 645, in send
    r = adapter.send(request, **kwargs)
  File "/Users/livionmbp/opt/anaconda3/envs/cleanrl/lib/python3.9/site-packages/requests/adapters.py", line 501, in send
    raise ConnectionError(err, request=request)
wandb.sdk.lib.retry.TransientError: None
2022-12-09 20:24:54,699 ERROR   Thread-13 :3275 [internal_api.py:upload_file():1612] upload_file exception https://storage.googleapis.com/wandb-production.appspot.com/livion/GridWorld/po5cuaz3/diff.patch?Expires=1670675093&GoogleAccessId=wandb-production%40appspot.gserviceaccount.com&Signature=ir3Y4stRUyjhJf3sq8Alayogz15KvLnBSX1%2BBiiq0QdxXqONLdU6NQMFuBLaMakTaVFUc0WBVpTmbYP65VEQ8We89gKeGdCRtpU9j6AtZZ1IRvT%2BlSgK2vNzFa4Jk81FkmNq419QS0nLBpAuGXarXYXlq2xVL3NbQqxD2CaQJVxSFlEJmC3B4AZmOfFOZv9%2FnQ0%2B%2FwRDxYsVPODEuDD6uHxsu0OkqROb25EjOT7Sy4A%2Bi8ecrShs3a6%2FxaGPWhyHS618XPaW8vtLHm5DrsjeW51wflvt6EYAcqBhmVv7oOnQr3tPLw1OoYvIYxI5sJY0wlqe18TcdcLcJUbLZCT0SQ%3D%3D: ('Connection aborted.', ConnectionResetError(54, 'Connection reset by peer'))
2022-12-09 20:24:54,699 ERROR   Thread-13 :3275 [internal_api.py:upload_file():1614] upload_file request headers: {'User-Agent': 'python-requests/2.27.1', 'Accept-Encoding': 'gzip, deflate', 'Accept': '*/*', 'Connection': 'keep-alive', 'Content-Length': '3348'}
2022-12-09 20:24:54,699 ERROR   Thread-13 :3275 [internal_api.py:upload_file():1616] upload_file response body: 
2022-12-09 20:24:54,699 ERROR   Thread-13 :3275 [retry.py:__call__():126] Retry attempt failed:
Traceback (most recent call last):
  File "/Users/livionmbp/opt/anaconda3/envs/cleanrl/lib/python3.9/site-packages/urllib3/connectionpool.py", line 703, in urlopen
    httplib_response = self._make_request(
  File "/Users/livionmbp/opt/anaconda3/envs/cleanrl/lib/python3.9/site-packages/urllib3/connectionpool.py", line 386, in _make_request
    self._validate_conn(conn)
  File "/Users/livionmbp/opt/anaconda3/envs/cleanrl/lib/python3.9/site-packages/urllib3/connectionpool.py", line 1040, in _validate_conn
    conn.connect()
  File "/Users/livionmbp/opt/anaconda3/envs/cleanrl/lib/python3.9/site-packages/urllib3/connection.py", line 416, in connect
    self.sock = ssl_wrap_socket(
  File "/Users/livionmbp/opt/anaconda3/envs/cleanrl/lib/python3.9/site-packages/urllib3/util/ssl_.py", line 449, in ssl_wrap_socket
    ssl_sock = _ssl_wrap_socket_impl(
  File "/Users/livionmbp/opt/anaconda3/envs/cleanrl/lib/python3.9/site-packages/urllib3/util/ssl_.py", line 493, in _ssl_wrap_socket_impl
    return ssl_context.wrap_socket(sock, server_hostname=server_hostname)
  File "/Users/livionmbp/opt/anaconda3/envs/cleanrl/lib/python3.9/ssl.py", line 501, in wrap_socket
    return self.sslsocket_class._create(
  File "/Users/livionmbp/opt/anaconda3/envs/cleanrl/lib/python3.9/ssl.py", line 1041, in _create
    self.do_handshake()
  File "/Users/livionmbp/opt/anaconda3/envs/cleanrl/lib/python3.9/ssl.py", line 1310, in do_handshake
    self._sslobj.do_handshake()
ConnectionResetError: [Errno 54] Connection reset by peer

During handling of the above exception, another exception occurred:

Traceback (most recent call last):
  File "/Users/livionmbp/opt/anaconda3/envs/cleanrl/lib/python3.9/site-packages/requests/adapters.py", line 440, in send
    resp = conn.urlopen(
  File "/Users/livionmbp/opt/anaconda3/envs/cleanrl/lib/python3.9/site-packages/urllib3/connectionpool.py", line 785, in urlopen
    retries = retries.increment(
  File "/Users/livionmbp/opt/anaconda3/envs/cleanrl/lib/python3.9/site-packages/urllib3/util/retry.py", line 550, in increment
    raise six.reraise(type(error), error, _stacktrace)
  File "/Users/livionmbp/opt/anaconda3/envs/cleanrl/lib/python3.9/site-packages/urllib3/packages/six.py", line 769, in reraise
    raise value.with_traceback(tb)
  File "/Users/livionmbp/opt/anaconda3/envs/cleanrl/lib/python3.9/site-packages/urllib3/connectionpool.py", line 703, in urlopen
    httplib_response = self._make_request(
  File "/Users/livionmbp/opt/anaconda3/envs/cleanrl/lib/python3.9/site-packages/urllib3/connectionpool.py", line 386, in _make_request
    self._validate_conn(conn)
  File "/Users/livionmbp/opt/anaconda3/envs/cleanrl/lib/python3.9/site-packages/urllib3/connectionpool.py", line 1040, in _validate_conn
    conn.connect()
  File "/Users/livionmbp/opt/anaconda3/envs/cleanrl/lib/python3.9/site-packages/urllib3/connection.py", line 416, in connect
    self.sock = ssl_wrap_socket(
  File "/Users/livionmbp/opt/anaconda3/envs/cleanrl/lib/python3.9/site-packages/urllib3/util/ssl_.py", line 449, in ssl_wrap_socket
    ssl_sock = _ssl_wrap_socket_impl(
  File "/Users/livionmbp/opt/anaconda3/envs/cleanrl/lib/python3.9/site-packages/urllib3/util/ssl_.py", line 493, in _ssl_wrap_socket_impl
    return ssl_context.wrap_socket(sock, server_hostname=server_hostname)
  File "/Users/livionmbp/opt/anaconda3/envs/cleanrl/lib/python3.9/ssl.py", line 501, in wrap_socket
    return self.sslsocket_class._create(
  File "/Users/livionmbp/opt/anaconda3/envs/cleanrl/lib/python3.9/ssl.py", line 1041, in _create
    self.do_handshake()
  File "/Users/livionmbp/opt/anaconda3/envs/cleanrl/lib/python3.9/ssl.py", line 1310, in do_handshake
    self._sslobj.do_handshake()
urllib3.exceptions.ProtocolError: ('Connection aborted.', ConnectionResetError(54, 'Connection reset by peer'))

During handling of the above exception, another exception occurred:

Traceback (most recent call last):
  File "/Users/livionmbp/opt/anaconda3/envs/cleanrl/lib/python3.9/site-packages/wandb/sdk/internal/internal_api.py", line 1609, in upload_file
    response = requests.put(url, data=progress, headers=extra_headers)
  File "/Users/livionmbp/opt/anaconda3/envs/cleanrl/lib/python3.9/site-packages/requests/api.py", line 132, in put
    return request('put', url, data=data, **kwargs)
  File "/Users/livionmbp/opt/anaconda3/envs/cleanrl/lib/python3.9/site-packages/requests/api.py", line 61, in request
    return session.request(method=method, url=url, **kwargs)
  File "/Users/livionmbp/opt/anaconda3/envs/cleanrl/lib/python3.9/site-packages/requests/sessions.py", line 529, in request
    resp = self.send(prep, **send_kwargs)
  File "/Users/livionmbp/opt/anaconda3/envs/cleanrl/lib/python3.9/site-packages/requests/sessions.py", line 645, in send
    r = adapter.send(request, **kwargs)
  File "/Users/livionmbp/opt/anaconda3/envs/cleanrl/lib/python3.9/site-packages/requests/adapters.py", line 501, in send
    raise ConnectionError(err, request=request)
requests.exceptions.ConnectionError: ('Connection aborted.', ConnectionResetError(54, 'Connection reset by peer'))

During handling of the above exception, another exception occurred:

Traceback (most recent call last):
  File "/Users/livionmbp/opt/anaconda3/envs/cleanrl/lib/python3.9/site-packages/wandb/sdk/lib/retry.py", line 102, in __call__
    result = self._call_fn(*args, **kwargs)
  File "/Users/livionmbp/opt/anaconda3/envs/cleanrl/lib/python3.9/site-packages/wandb/sdk/internal/internal_api.py", line 1625, in upload_file
    six.reraise(type(e), e, sys.exc_info()[2])
  File "/Users/livionmbp/opt/anaconda3/envs/cleanrl/lib/python3.9/site-packages/six.py", line 718, in reraise
    raise value.with_traceback(tb)
  File "/Users/livionmbp/opt/anaconda3/envs/cleanrl/lib/python3.9/site-packages/wandb/sdk/internal/internal_api.py", line 1609, in upload_file
    response = requests.put(url, data=progress, headers=extra_headers)
  File "/Users/livionmbp/opt/anaconda3/envs/cleanrl/lib/python3.9/site-packages/requests/api.py", line 132, in put
    return request('put', url, data=data, **kwargs)
  File "/Users/livionmbp/opt/anaconda3/envs/cleanrl/lib/python3.9/site-packages/requests/api.py", line 61, in request
    return session.request(method=method, url=url, **kwargs)
  File "/Users/livionmbp/opt/anaconda3/envs/cleanrl/lib/python3.9/site-packages/requests/sessions.py", line 529, in request
    resp = self.send(prep, **send_kwargs)
  File "/Users/livionmbp/opt/anaconda3/envs/cleanrl/lib/python3.9/site-packages/requests/sessions.py", line 645, in send
    r = adapter.send(request, **kwargs)
  File "/Users/livionmbp/opt/anaconda3/envs/cleanrl/lib/python3.9/site-packages/requests/adapters.py", line 501, in send
    raise ConnectionError(err, request=request)
wandb.sdk.lib.retry.TransientError: None
2022-12-09 20:24:56,921 ERROR   Thread-11 :3275 [internal_api.py:upload_file():1612] upload_file exception https://storage.googleapis.com/wandb-production.appspot.com/livion/GridWorld/po5cuaz3/wandb-metadata.json?Expires=1670675092&GoogleAccessId=wandb-production%40appspot.gserviceaccount.com&Signature=RW9BzYjp2XBDJrfR6htGS1TPEXJS4bOOFwQsSiOCWiaUHO1SMuy6VxNbSeF8yTeRwBZz6HY9L57daE5tooTpMkIIDFWNH3L7opzPgdWL03tumm3ymi%2FH2UX4%2FVO5%2BFD8N%2FsF7Wmwu3QOVqV%2FtnHKCeXa2gHcHT%2BZgSH17r%2FpOt4%2F1hrCcZEyKsBfIznC%2BNtYr0DNne47BxZCcEY5XqbepU5Sd7RR3gPbZussP5P4QDORBQ1ViboCq9mxZroWYsZbMWdsbnqIEo88YU477sWCbszeC7TLhAiqA6zPW5Ox%2ByyEf2Q71n5B4wcMsMpE8ObULUPJ7y2N3cXIhjz%2BTOPZ5Q%3D%3D: ('Connection aborted.', ConnectionResetError(54, 'Connection reset by peer'))
2022-12-09 20:24:56,921 ERROR   Thread-11 :3275 [internal_api.py:upload_file():1614] upload_file request headers: {'User-Agent': 'python-requests/2.27.1', 'Accept-Encoding': 'gzip, deflate', 'Accept': '*/*', 'Connection': 'keep-alive', 'Content-Length': '854'}
2022-12-09 20:24:56,921 ERROR   Thread-11 :3275 [internal_api.py:upload_file():1616] upload_file response body: 
2022-12-09 20:24:57,410 ERROR   Thread-13 :3275 [internal_api.py:upload_file():1612] upload_file exception https://storage.googleapis.com/wandb-production.appspot.com/livion/GridWorld/po5cuaz3/diff.patch?Expires=1670675093&GoogleAccessId=wandb-production%40appspot.gserviceaccount.com&Signature=ir3Y4stRUyjhJf3sq8Alayogz15KvLnBSX1%2BBiiq0QdxXqONLdU6NQMFuBLaMakTaVFUc0WBVpTmbYP65VEQ8We89gKeGdCRtpU9j6AtZZ1IRvT%2BlSgK2vNzFa4Jk81FkmNq419QS0nLBpAuGXarXYXlq2xVL3NbQqxD2CaQJVxSFlEJmC3B4AZmOfFOZv9%2FnQ0%2B%2FwRDxYsVPODEuDD6uHxsu0OkqROb25EjOT7Sy4A%2Bi8ecrShs3a6%2FxaGPWhyHS618XPaW8vtLHm5DrsjeW51wflvt6EYAcqBhmVv7oOnQr3tPLw1OoYvIYxI5sJY0wlqe18TcdcLcJUbLZCT0SQ%3D%3D: ('Connection aborted.', ConnectionResetError(54, 'Connection reset by peer'))
2022-12-09 20:24:57,410 ERROR   Thread-13 :3275 [internal_api.py:upload_file():1614] upload_file request headers: {'User-Agent': 'python-requests/2.27.1', 'Accept-Encoding': 'gzip, deflate', 'Accept': '*/*', 'Connection': 'keep-alive', 'Content-Length': '3348'}
2022-12-09 20:24:57,411 ERROR   Thread-13 :3275 [internal_api.py:upload_file():1616] upload_file response body: 
2022-12-09 20:25:01,509 ERROR   Thread-11 :3275 [internal_api.py:upload_file():1612] upload_file exception https://storage.googleapis.com/wandb-production.appspot.com/livion/GridWorld/po5cuaz3/wandb-metadata.json?Expires=1670675092&GoogleAccessId=wandb-production%40appspot.gserviceaccount.com&Signature=RW9BzYjp2XBDJrfR6htGS1TPEXJS4bOOFwQsSiOCWiaUHO1SMuy6VxNbSeF8yTeRwBZz6HY9L57daE5tooTpMkIIDFWNH3L7opzPgdWL03tumm3ymi%2FH2UX4%2FVO5%2BFD8N%2FsF7Wmwu3QOVqV%2FtnHKCeXa2gHcHT%2BZgSH17r%2FpOt4%2F1hrCcZEyKsBfIznC%2BNtYr0DNne47BxZCcEY5XqbepU5Sd7RR3gPbZussP5P4QDORBQ1ViboCq9mxZroWYsZbMWdsbnqIEo88YU477sWCbszeC7TLhAiqA6zPW5Ox%2ByyEf2Q71n5B4wcMsMpE8ObULUPJ7y2N3cXIhjz%2BTOPZ5Q%3D%3D: ('Connection aborted.', ConnectionResetError(54, 'Connection reset by peer'))
2022-12-09 20:25:01,509 ERROR   Thread-11 :3275 [internal_api.py:upload_file():1614] upload_file request headers: {'User-Agent': 'python-requests/2.27.1', 'Accept-Encoding': 'gzip, deflate', 'Accept': '*/*', 'Connection': 'keep-alive', 'Content-Length': '854'}
2022-12-09 20:25:01,509 ERROR   Thread-11 :3275 [internal_api.py:upload_file():1616] upload_file response body: 
2022-12-09 20:25:01,760 ERROR   Thread-13 :3275 [internal_api.py:upload_file():1612] upload_file exception https://storage.googleapis.com/wandb-production.appspot.com/livion/GridWorld/po5cuaz3/diff.patch?Expires=1670675093&GoogleAccessId=wandb-production%40appspot.gserviceaccount.com&Signature=ir3Y4stRUyjhJf3sq8Alayogz15KvLnBSX1%2BBiiq0QdxXqONLdU6NQMFuBLaMakTaVFUc0WBVpTmbYP65VEQ8We89gKeGdCRtpU9j6AtZZ1IRvT%2BlSgK2vNzFa4Jk81FkmNq419QS0nLBpAuGXarXYXlq2xVL3NbQqxD2CaQJVxSFlEJmC3B4AZmOfFOZv9%2FnQ0%2B%2FwRDxYsVPODEuDD6uHxsu0OkqROb25EjOT7Sy4A%2Bi8ecrShs3a6%2FxaGPWhyHS618XPaW8vtLHm5DrsjeW51wflvt6EYAcqBhmVv7oOnQr3tPLw1OoYvIYxI5sJY0wlqe18TcdcLcJUbLZCT0SQ%3D%3D: ('Connection aborted.', ConnectionResetError(54, 'Connection reset by peer'))
2022-12-09 20:25:01,761 ERROR   Thread-13 :3275 [internal_api.py:upload_file():1614] upload_file request headers: {'User-Agent': 'python-requests/2.27.1', 'Accept-Encoding': 'gzip, deflate', 'Accept': '*/*', 'Connection': 'keep-alive', 'Content-Length': '3348'}
2022-12-09 20:25:01,761 ERROR   Thread-13 :3275 [internal_api.py:upload_file():1616] upload_file response body: 
2022-12-09 20:25:10,457 WARNING MainThread:3275 [internal.py:wandb_internal():155] Internal process interrupt: 2
2022-12-09 20:25:10,458 ERROR   MainThread:3275 [internal.py:wandb_internal():158] Internal process interrupted.
2022-12-09 20:25:11,064 ERROR   Thread-11 :3275 [internal_api.py:upload_file():1612] upload_file exception https://storage.googleapis.com/wandb-production.appspot.com/livion/GridWorld/po5cuaz3/wandb-metadata.json?Expires=1670675092&GoogleAccessId=wandb-production%40appspot.gserviceaccount.com&Signature=RW9BzYjp2XBDJrfR6htGS1TPEXJS4bOOFwQsSiOCWiaUHO1SMuy6VxNbSeF8yTeRwBZz6HY9L57daE5tooTpMkIIDFWNH3L7opzPgdWL03tumm3ymi%2FH2UX4%2FVO5%2BFD8N%2FsF7Wmwu3QOVqV%2FtnHKCeXa2gHcHT%2BZgSH17r%2FpOt4%2F1hrCcZEyKsBfIznC%2BNtYr0DNne47BxZCcEY5XqbepU5Sd7RR3gPbZussP5P4QDORBQ1ViboCq9mxZroWYsZbMWdsbnqIEo88YU477sWCbszeC7TLhAiqA6zPW5Ox%2ByyEf2Q71n5B4wcMsMpE8ObULUPJ7y2N3cXIhjz%2BTOPZ5Q%3D%3D: ('Connection aborted.', ConnectionResetError(54, 'Connection reset by peer'))
2022-12-09 20:25:11,064 ERROR   Thread-11 :3275 [internal_api.py:upload_file():1614] upload_file request headers: {'User-Agent': 'python-requests/2.27.1', 'Accept-Encoding': 'gzip, deflate', 'Accept': '*/*', 'Connection': 'keep-alive', 'Content-Length': '854'}
2022-12-09 20:25:11,064 ERROR   Thread-11 :3275 [internal_api.py:upload_file():1616] upload_file response body: 
2022-12-09 20:25:11,146 INFO    HandlerThread:3275 [handler.py:finish():778] shutting down handler
2022-12-09 20:25:11,147 ERROR   Thread-13 :3275 [internal_api.py:upload_file():1612] upload_file exception https://storage.googleapis.com/wandb-production.appspot.com/livion/GridWorld/po5cuaz3/diff.patch?Expires=1670675093&GoogleAccessId=wandb-production%40appspot.gserviceaccount.com&Signature=ir3Y4stRUyjhJf3sq8Alayogz15KvLnBSX1%2BBiiq0QdxXqONLdU6NQMFuBLaMakTaVFUc0WBVpTmbYP65VEQ8We89gKeGdCRtpU9j6AtZZ1IRvT%2BlSgK2vNzFa4Jk81FkmNq419QS0nLBpAuGXarXYXlq2xVL3NbQqxD2CaQJVxSFlEJmC3B4AZmOfFOZv9%2FnQ0%2B%2FwRDxYsVPODEuDD6uHxsu0OkqROb25EjOT7Sy4A%2Bi8ecrShs3a6%2FxaGPWhyHS618XPaW8vtLHm5DrsjeW51wflvt6EYAcqBhmVv7oOnQr3tPLw1OoYvIYxI5sJY0wlqe18TcdcLcJUbLZCT0SQ%3D%3D: ('Connection aborted.', ConnectionResetError(54, 'Connection reset by peer'))
2022-12-09 20:25:11,148 ERROR   Thread-13 :3275 [internal_api.py:upload_file():1614] upload_file request headers: {'User-Agent': 'python-requests/2.27.1', 'Accept-Encoding': 'gzip, deflate', 'Accept': '*/*', 'Connection': 'keep-alive', 'Content-Length': '3348'}
2022-12-09 20:25:11,148 ERROR   Thread-13 :3275 [internal_api.py:upload_file():1616] upload_file response body: 
2022-12-09 20:25:11,202 INFO    SenderThread:3275 [sender.py:finish():1078] shutting down sender
2022-12-09 20:25:11,202 INFO    SenderThread:3275 [dir_watcher.py:finish():283] shutting down directory watcher
2022-12-09 20:25:11,212 INFO    WriterThread:3275 [datastore.py:close():281] close: /Users/livionmbp/Documents/GitHub/Sources/3DGridWorld/wandb/run-20221209_202446-po5cuaz3/run-po5cuaz3.wandb
2022-12-09 20:25:11,337 INFO    SenderThread:3275 [dir_watcher.py:finish():313] scan: /Users/livionmbp/Documents/GitHub/Sources/3DGridWorld/wandb/run-20221209_202446-po5cuaz3/files
2022-12-09 20:25:11,354 INFO    SenderThread:3275 [dir_watcher.py:finish():327] scan save: /Users/livionmbp/Documents/GitHub/Sources/3DGridWorld/wandb/run-20221209_202446-po5cuaz3/files/diff.patch diff.patch
2022-12-09 20:25:11,354 INFO    SenderThread:3275 [dir_watcher.py:finish():327] scan save: /Users/livionmbp/Documents/GitHub/Sources/3DGridWorld/wandb/run-20221209_202446-po5cuaz3/files/requirements.txt requirements.txt
2022-12-09 20:25:11,354 INFO    SenderThread:3275 [dir_watcher.py:finish():327] scan save: /Users/livionmbp/Documents/GitHub/Sources/3DGridWorld/wandb/run-20221209_202446-po5cuaz3/files/config.yaml config.yaml
2022-12-09 20:25:11,364 INFO    SenderThread:3275 [dir_watcher.py:finish():327] scan save: /Users/livionmbp/Documents/GitHub/Sources/3DGridWorld/wandb/run-20221209_202446-po5cuaz3/files/wandb-summary.json wandb-summary.json
2022-12-09 20:25:11,368 INFO    SenderThread:3275 [dir_watcher.py:finish():327] scan save: /Users/livionmbp/Documents/GitHub/Sources/3DGridWorld/wandb/run-20221209_202446-po5cuaz3/files/conda-environment.yaml conda-environment.yaml
2022-12-09 20:25:11,372 INFO    SenderThread:3275 [dir_watcher.py:finish():327] scan save: /Users/livionmbp/Documents/GitHub/Sources/3DGridWorld/wandb/run-20221209_202446-po5cuaz3/files/wandb-metadata.json wandb-metadata.json
2022-12-09 20:25:11,373 INFO    SenderThread:3275 [dir_watcher.py:finish():327] scan save: /Users/livionmbp/Documents/GitHub/Sources/3DGridWorld/wandb/run-20221209_202446-po5cuaz3/files/code/PPOagent.py code/PPOagent.py
2022-12-09 20:25:11,373 INFO    SenderThread:3275 [file_pusher.py:finish():145] shutting down file pusher
2022-12-09 20:25:11,373 INFO    SenderThread:3275 [file_pusher.py:join():150] waiting for file pusher
2022-12-09 20:25:28,567 ERROR   Thread-11 :3275 [internal_api.py:upload_file():1612] upload_file exception https://storage.googleapis.com/wandb-production.appspot.com/livion/GridWorld/po5cuaz3/wandb-metadata.json?Expires=1670675092&GoogleAccessId=wandb-production%40appspot.gserviceaccount.com&Signature=RW9BzYjp2XBDJrfR6htGS1TPEXJS4bOOFwQsSiOCWiaUHO1SMuy6VxNbSeF8yTeRwBZz6HY9L57daE5tooTpMkIIDFWNH3L7opzPgdWL03tumm3ymi%2FH2UX4%2FVO5%2BFD8N%2FsF7Wmwu3QOVqV%2FtnHKCeXa2gHcHT%2BZgSH17r%2FpOt4%2F1hrCcZEyKsBfIznC%2BNtYr0DNne47BxZCcEY5XqbepU5Sd7RR3gPbZussP5P4QDORBQ1ViboCq9mxZroWYsZbMWdsbnqIEo88YU477sWCbszeC7TLhAiqA6zPW5Ox%2ByyEf2Q71n5B4wcMsMpE8ObULUPJ7y2N3cXIhjz%2BTOPZ5Q%3D%3D: ('Connection aborted.', ConnectionResetError(54, 'Connection reset by peer'))
2022-12-09 20:25:28,567 ERROR   Thread-11 :3275 [internal_api.py:upload_file():1614] upload_file request headers: {'User-Agent': 'python-requests/2.27.1', 'Accept-Encoding': 'gzip, deflate', 'Accept': '*/*', 'Connection': 'keep-alive', 'Content-Length': '854'}
2022-12-09 20:25:28,567 ERROR   Thread-11 :3275 [internal_api.py:upload_file():1616] upload_file response body: 
2022-12-09 20:25:29,129 ERROR   Thread-13 :3275 [internal_api.py:upload_file():1612] upload_file exception https://storage.googleapis.com/wandb-production.appspot.com/livion/GridWorld/po5cuaz3/diff.patch?Expires=1670675093&GoogleAccessId=wandb-production%40appspot.gserviceaccount.com&Signature=ir3Y4stRUyjhJf3sq8Alayogz15KvLnBSX1%2BBiiq0QdxXqONLdU6NQMFuBLaMakTaVFUc0WBVpTmbYP65VEQ8We89gKeGdCRtpU9j6AtZZ1IRvT%2BlSgK2vNzFa4Jk81FkmNq419QS0nLBpAuGXarXYXlq2xVL3NbQqxD2CaQJVxSFlEJmC3B4AZmOfFOZv9%2FnQ0%2B%2FwRDxYsVPODEuDD6uHxsu0OkqROb25EjOT7Sy4A%2Bi8ecrShs3a6%2FxaGPWhyHS618XPaW8vtLHm5DrsjeW51wflvt6EYAcqBhmVv7oOnQr3tPLw1OoYvIYxI5sJY0wlqe18TcdcLcJUbLZCT0SQ%3D%3D: ('Connection aborted.', ConnectionResetError(54, 'Connection reset by peer'))
2022-12-09 20:25:29,129 ERROR   Thread-13 :3275 [internal_api.py:upload_file():1614] upload_file request headers: {'User-Agent': 'python-requests/2.27.1', 'Accept-Encoding': 'gzip, deflate', 'Accept': '*/*', 'Connection': 'keep-alive', 'Content-Length': '3348'}
2022-12-09 20:25:29,129 ERROR   Thread-13 :3275 [internal_api.py:upload_file():1616] upload_file response body: 
2022-12-09 20:26:02,820 ERROR   Thread-13 :3275 [internal_api.py:upload_file():1612] upload_file exception https://storage.googleapis.com/wandb-production.appspot.com/livion/GridWorld/po5cuaz3/diff.patch?Expires=1670675093&GoogleAccessId=wandb-production%40appspot.gserviceaccount.com&Signature=ir3Y4stRUyjhJf3sq8Alayogz15KvLnBSX1%2BBiiq0QdxXqONLdU6NQMFuBLaMakTaVFUc0WBVpTmbYP65VEQ8We89gKeGdCRtpU9j6AtZZ1IRvT%2BlSgK2vNzFa4Jk81FkmNq419QS0nLBpAuGXarXYXlq2xVL3NbQqxD2CaQJVxSFlEJmC3B4AZmOfFOZv9%2FnQ0%2B%2FwRDxYsVPODEuDD6uHxsu0OkqROb25EjOT7Sy4A%2Bi8ecrShs3a6%2FxaGPWhyHS618XPaW8vtLHm5DrsjeW51wflvt6EYAcqBhmVv7oOnQr3tPLw1OoYvIYxI5sJY0wlqe18TcdcLcJUbLZCT0SQ%3D%3D: ('Connection aborted.', ConnectionResetError(54, 'Connection reset by peer'))
2022-12-09 20:26:02,821 ERROR   Thread-13 :3275 [internal_api.py:upload_file():1614] upload_file request headers: {'User-Agent': 'python-requests/2.27.1', 'Accept-Encoding': 'gzip, deflate', 'Accept': '*/*', 'Connection': 'keep-alive', 'Content-Length': '3348'}
2022-12-09 20:26:02,821 ERROR   Thread-13 :3275 [internal_api.py:upload_file():1616] upload_file response body: 
2022-12-09 20:26:05,748 ERROR   Thread-11 :3275 [internal_api.py:upload_file():1612] upload_file exception https://storage.googleapis.com/wandb-production.appspot.com/livion/GridWorld/po5cuaz3/wandb-metadata.json?Expires=1670675092&GoogleAccessId=wandb-production%40appspot.gserviceaccount.com&Signature=RW9BzYjp2XBDJrfR6htGS1TPEXJS4bOOFwQsSiOCWiaUHO1SMuy6VxNbSeF8yTeRwBZz6HY9L57daE5tooTpMkIIDFWNH3L7opzPgdWL03tumm3ymi%2FH2UX4%2FVO5%2BFD8N%2FsF7Wmwu3QOVqV%2FtnHKCeXa2gHcHT%2BZgSH17r%2FpOt4%2F1hrCcZEyKsBfIznC%2BNtYr0DNne47BxZCcEY5XqbepU5Sd7RR3gPbZussP5P4QDORBQ1ViboCq9mxZroWYsZbMWdsbnqIEo88YU477sWCbszeC7TLhAiqA6zPW5Ox%2ByyEf2Q71n5B4wcMsMpE8ObULUPJ7y2N3cXIhjz%2BTOPZ5Q%3D%3D: ('Connection aborted.', ConnectionResetError(54, 'Connection reset by peer'))
2022-12-09 20:26:05,749 ERROR   Thread-11 :3275 [internal_api.py:upload_file():1614] upload_file request headers: {'User-Agent': 'python-requests/2.27.1', 'Accept-Encoding': 'gzip, deflate', 'Accept': '*/*', 'Connection': 'keep-alive', 'Content-Length': '854'}
2022-12-09 20:26:05,749 ERROR   Thread-11 :3275 [internal_api.py:upload_file():1616] upload_file response body: 
2022-12-09 20:27:16,852 ERROR   Thread-13 :3275 [internal_api.py:upload_file():1612] upload_file exception https://storage.googleapis.com/wandb-production.appspot.com/livion/GridWorld/po5cuaz3/diff.patch?Expires=1670675093&GoogleAccessId=wandb-production%40appspot.gserviceaccount.com&Signature=ir3Y4stRUyjhJf3sq8Alayogz15KvLnBSX1%2BBiiq0QdxXqONLdU6NQMFuBLaMakTaVFUc0WBVpTmbYP65VEQ8We89gKeGdCRtpU9j6AtZZ1IRvT%2BlSgK2vNzFa4Jk81FkmNq419QS0nLBpAuGXarXYXlq2xVL3NbQqxD2CaQJVxSFlEJmC3B4AZmOfFOZv9%2FnQ0%2B%2FwRDxYsVPODEuDD6uHxsu0OkqROb25EjOT7Sy4A%2Bi8ecrShs3a6%2FxaGPWhyHS618XPaW8vtLHm5DrsjeW51wflvt6EYAcqBhmVv7oOnQr3tPLw1OoYvIYxI5sJY0wlqe18TcdcLcJUbLZCT0SQ%3D%3D: ('Connection aborted.', ConnectionResetError(54, 'Connection reset by peer'))
2022-12-09 20:27:16,853 ERROR   Thread-13 :3275 [internal_api.py:upload_file():1614] upload_file request headers: {'User-Agent': 'python-requests/2.27.1', 'Accept-Encoding': 'gzip, deflate', 'Accept': '*/*', 'Connection': 'keep-alive', 'Content-Length': '3348'}
2022-12-09 20:27:16,853 ERROR   Thread-13 :3275 [internal_api.py:upload_file():1616] upload_file response body: 
2022-12-09 20:27:20,066 ERROR   Thread-11 :3275 [internal_api.py:upload_file():1612] upload_file exception https://storage.googleapis.com/wandb-production.appspot.com/livion/GridWorld/po5cuaz3/wandb-metadata.json?Expires=1670675092&GoogleAccessId=wandb-production%40appspot.gserviceaccount.com&Signature=RW9BzYjp2XBDJrfR6htGS1TPEXJS4bOOFwQsSiOCWiaUHO1SMuy6VxNbSeF8yTeRwBZz6HY9L57daE5tooTpMkIIDFWNH3L7opzPgdWL03tumm3ymi%2FH2UX4%2FVO5%2BFD8N%2FsF7Wmwu3QOVqV%2FtnHKCeXa2gHcHT%2BZgSH17r%2FpOt4%2F1hrCcZEyKsBfIznC%2BNtYr0DNne47BxZCcEY5XqbepU5Sd7RR3gPbZussP5P4QDORBQ1ViboCq9mxZroWYsZbMWdsbnqIEo88YU477sWCbszeC7TLhAiqA6zPW5Ox%2ByyEf2Q71n5B4wcMsMpE8ObULUPJ7y2N3cXIhjz%2BTOPZ5Q%3D%3D: ('Connection aborted.', ConnectionResetError(54, 'Connection reset by peer'))
2022-12-09 20:27:20,066 ERROR   Thread-11 :3275 [internal_api.py:upload_file():1614] upload_file request headers: {'User-Agent': 'python-requests/2.27.1', 'Accept-Encoding': 'gzip, deflate', 'Accept': '*/*', 'Connection': 'keep-alive', 'Content-Length': '854'}
2022-12-09 20:27:20,066 ERROR   Thread-11 :3275 [internal_api.py:upload_file():1616] upload_file response body: 
2022-12-09 20:29:29,569 ERROR   Thread-11 :3275 [internal_api.py:upload_file():1612] upload_file exception https://storage.googleapis.com/wandb-production.appspot.com/livion/GridWorld/po5cuaz3/wandb-metadata.json?Expires=1670675092&GoogleAccessId=wandb-production%40appspot.gserviceaccount.com&Signature=RW9BzYjp2XBDJrfR6htGS1TPEXJS4bOOFwQsSiOCWiaUHO1SMuy6VxNbSeF8yTeRwBZz6HY9L57daE5tooTpMkIIDFWNH3L7opzPgdWL03tumm3ymi%2FH2UX4%2FVO5%2BFD8N%2FsF7Wmwu3QOVqV%2FtnHKCeXa2gHcHT%2BZgSH17r%2FpOt4%2F1hrCcZEyKsBfIznC%2BNtYr0DNne47BxZCcEY5XqbepU5Sd7RR3gPbZussP5P4QDORBQ1ViboCq9mxZroWYsZbMWdsbnqIEo88YU477sWCbszeC7TLhAiqA6zPW5Ox%2ByyEf2Q71n5B4wcMsMpE8ObULUPJ7y2N3cXIhjz%2BTOPZ5Q%3D%3D: ('Connection aborted.', ConnectionResetError(54, 'Connection reset by peer'))
2022-12-09 20:29:29,570 ERROR   Thread-11 :3275 [internal_api.py:upload_file():1614] upload_file request headers: {'User-Agent': 'python-requests/2.27.1', 'Accept-Encoding': 'gzip, deflate', 'Accept': '*/*', 'Connection': 'keep-alive', 'Content-Length': '854'}
2022-12-09 20:29:29,570 ERROR   Thread-11 :3275 [internal_api.py:upload_file():1616] upload_file response body: 
2022-12-09 20:29:49,624 ERROR   Thread-13 :3275 [internal_api.py:upload_file():1612] upload_file exception https://storage.googleapis.com/wandb-production.appspot.com/livion/GridWorld/po5cuaz3/diff.patch?Expires=1670675093&GoogleAccessId=wandb-production%40appspot.gserviceaccount.com&Signature=ir3Y4stRUyjhJf3sq8Alayogz15KvLnBSX1%2BBiiq0QdxXqONLdU6NQMFuBLaMakTaVFUc0WBVpTmbYP65VEQ8We89gKeGdCRtpU9j6AtZZ1IRvT%2BlSgK2vNzFa4Jk81FkmNq419QS0nLBpAuGXarXYXlq2xVL3NbQqxD2CaQJVxSFlEJmC3B4AZmOfFOZv9%2FnQ0%2B%2FwRDxYsVPODEuDD6uHxsu0OkqROb25EjOT7Sy4A%2Bi8ecrShs3a6%2FxaGPWhyHS618XPaW8vtLHm5DrsjeW51wflvt6EYAcqBhmVv7oOnQr3tPLw1OoYvIYxI5sJY0wlqe18TcdcLcJUbLZCT0SQ%3D%3D: ('Connection aborted.', ConnectionResetError(54, 'Connection reset by peer'))
2022-12-09 20:29:49,625 ERROR   Thread-13 :3275 [internal_api.py:upload_file():1614] upload_file request headers: {'User-Agent': 'python-requests/2.27.1', 'Accept-Encoding': 'gzip, deflate', 'Accept': '*/*', 'Connection': 'keep-alive', 'Content-Length': '3348'}
2022-12-09 20:29:49,625 ERROR   Thread-13 :3275 [internal_api.py:upload_file():1616] upload_file response body: 
2022-12-09 20:34:00,341 ERROR   Thread-11 :3275 [internal_api.py:upload_file():1612] upload_file exception https://storage.googleapis.com/wandb-production.appspot.com/livion/GridWorld/po5cuaz3/wandb-metadata.json?Expires=1670675092&GoogleAccessId=wandb-production%40appspot.gserviceaccount.com&Signature=RW9BzYjp2XBDJrfR6htGS1TPEXJS4bOOFwQsSiOCWiaUHO1SMuy6VxNbSeF8yTeRwBZz6HY9L57daE5tooTpMkIIDFWNH3L7opzPgdWL03tumm3ymi%2FH2UX4%2FVO5%2BFD8N%2FsF7Wmwu3QOVqV%2FtnHKCeXa2gHcHT%2BZgSH17r%2FpOt4%2F1hrCcZEyKsBfIznC%2BNtYr0DNne47BxZCcEY5XqbepU5Sd7RR3gPbZussP5P4QDORBQ1ViboCq9mxZroWYsZbMWdsbnqIEo88YU477sWCbszeC7TLhAiqA6zPW5Ox%2ByyEf2Q71n5B4wcMsMpE8ObULUPJ7y2N3cXIhjz%2BTOPZ5Q%3D%3D: ('Connection aborted.', ConnectionResetError(54, 'Connection reset by peer'))
2022-12-09 20:34:00,342 ERROR   Thread-11 :3275 [internal_api.py:upload_file():1614] upload_file request headers: {'User-Agent': 'python-requests/2.27.1', 'Accept-Encoding': 'gzip, deflate', 'Accept': '*/*', 'Connection': 'keep-alive', 'Content-Length': '854'}
2022-12-09 20:34:00,342 ERROR   Thread-11 :3275 [internal_api.py:upload_file():1616] upload_file response body: 
2022-12-09 20:34:21,661 ERROR   Thread-13 :3275 [internal_api.py:upload_file():1612] upload_file exception https://storage.googleapis.com/wandb-production.appspot.com/livion/GridWorld/po5cuaz3/diff.patch?Expires=1670675093&GoogleAccessId=wandb-production%40appspot.gserviceaccount.com&Signature=ir3Y4stRUyjhJf3sq8Alayogz15KvLnBSX1%2BBiiq0QdxXqONLdU6NQMFuBLaMakTaVFUc0WBVpTmbYP65VEQ8We89gKeGdCRtpU9j6AtZZ1IRvT%2BlSgK2vNzFa4Jk81FkmNq419QS0nLBpAuGXarXYXlq2xVL3NbQqxD2CaQJVxSFlEJmC3B4AZmOfFOZv9%2FnQ0%2B%2FwRDxYsVPODEuDD6uHxsu0OkqROb25EjOT7Sy4A%2Bi8ecrShs3a6%2FxaGPWhyHS618XPaW8vtLHm5DrsjeW51wflvt6EYAcqBhmVv7oOnQr3tPLw1OoYvIYxI5sJY0wlqe18TcdcLcJUbLZCT0SQ%3D%3D: ('Connection aborted.', ConnectionResetError(54, 'Connection reset by peer'))
2022-12-09 20:34:21,661 ERROR   Thread-13 :3275 [internal_api.py:upload_file():1614] upload_file request headers: {'User-Agent': 'python-requests/2.27.1', 'Accept-Encoding': 'gzip, deflate', 'Accept': '*/*', 'Connection': 'keep-alive', 'Content-Length': '3348'}
2022-12-09 20:34:21,661 ERROR   Thread-13 :3275 [internal_api.py:upload_file():1616] upload_file response body: 
2022-12-09 20:39:24,638 ERROR   Thread-13 :3275 [internal_api.py:upload_file():1612] upload_file exception https://storage.googleapis.com/wandb-production.appspot.com/livion/GridWorld/po5cuaz3/diff.patch?Expires=1670675093&GoogleAccessId=wandb-production%40appspot.gserviceaccount.com&Signature=ir3Y4stRUyjhJf3sq8Alayogz15KvLnBSX1%2BBiiq0QdxXqONLdU6NQMFuBLaMakTaVFUc0WBVpTmbYP65VEQ8We89gKeGdCRtpU9j6AtZZ1IRvT%2BlSgK2vNzFa4Jk81FkmNq419QS0nLBpAuGXarXYXlq2xVL3NbQqxD2CaQJVxSFlEJmC3B4AZmOfFOZv9%2FnQ0%2B%2FwRDxYsVPODEuDD6uHxsu0OkqROb25EjOT7Sy4A%2Bi8ecrShs3a6%2FxaGPWhyHS618XPaW8vtLHm5DrsjeW51wflvt6EYAcqBhmVv7oOnQr3tPLw1OoYvIYxI5sJY0wlqe18TcdcLcJUbLZCT0SQ%3D%3D: ('Connection aborted.', ConnectionResetError(54, 'Connection reset by peer'))
2022-12-09 20:39:24,639 ERROR   Thread-13 :3275 [internal_api.py:upload_file():1614] upload_file request headers: {'User-Agent': 'python-requests/2.27.1', 'Accept-Encoding': 'gzip, deflate', 'Accept': '*/*', 'Connection': 'keep-alive', 'Content-Length': '3348'}
2022-12-09 20:39:24,639 ERROR   Thread-13 :3275 [internal_api.py:upload_file():1616] upload_file response body: 
2022-12-09 20:39:29,845 ERROR   Thread-11 :3275 [internal_api.py:upload_file():1612] upload_file exception https://storage.googleapis.com/wandb-production.appspot.com/livion/GridWorld/po5cuaz3/wandb-metadata.json?Expires=1670675092&GoogleAccessId=wandb-production%40appspot.gserviceaccount.com&Signature=RW9BzYjp2XBDJrfR6htGS1TPEXJS4bOOFwQsSiOCWiaUHO1SMuy6VxNbSeF8yTeRwBZz6HY9L57daE5tooTpMkIIDFWNH3L7opzPgdWL03tumm3ymi%2FH2UX4%2FVO5%2BFD8N%2FsF7Wmwu3QOVqV%2FtnHKCeXa2gHcHT%2BZgSH17r%2FpOt4%2F1hrCcZEyKsBfIznC%2BNtYr0DNne47BxZCcEY5XqbepU5Sd7RR3gPbZussP5P4QDORBQ1ViboCq9mxZroWYsZbMWdsbnqIEo88YU477sWCbszeC7TLhAiqA6zPW5Ox%2ByyEf2Q71n5B4wcMsMpE8ObULUPJ7y2N3cXIhjz%2BTOPZ5Q%3D%3D: ('Connection aborted.', ConnectionResetError(54, 'Connection reset by peer'))
2022-12-09 20:39:29,845 ERROR   Thread-11 :3275 [internal_api.py:upload_file():1614] upload_file request headers: {'User-Agent': 'python-requests/2.27.1', 'Accept-Encoding': 'gzip, deflate', 'Accept': '*/*', 'Connection': 'keep-alive', 'Content-Length': '854'}
2022-12-09 20:39:29,845 ERROR   Thread-11 :3275 [internal_api.py:upload_file():1616] upload_file response body: 
2022-12-09 20:44:37,596 ERROR   Thread-11 :3275 [internal_api.py:upload_file():1612] upload_file exception https://storage.googleapis.com/wandb-production.appspot.com/livion/GridWorld/po5cuaz3/wandb-metadata.json?Expires=1670675092&GoogleAccessId=wandb-production%40appspot.gserviceaccount.com&Signature=RW9BzYjp2XBDJrfR6htGS1TPEXJS4bOOFwQsSiOCWiaUHO1SMuy6VxNbSeF8yTeRwBZz6HY9L57daE5tooTpMkIIDFWNH3L7opzPgdWL03tumm3ymi%2FH2UX4%2FVO5%2BFD8N%2FsF7Wmwu3QOVqV%2FtnHKCeXa2gHcHT%2BZgSH17r%2FpOt4%2F1hrCcZEyKsBfIznC%2BNtYr0DNne47BxZCcEY5XqbepU5Sd7RR3gPbZussP5P4QDORBQ1ViboCq9mxZroWYsZbMWdsbnqIEo88YU477sWCbszeC7TLhAiqA6zPW5Ox%2ByyEf2Q71n5B4wcMsMpE8ObULUPJ7y2N3cXIhjz%2BTOPZ5Q%3D%3D: ('Connection aborted.', ConnectionResetError(54, 'Connection reset by peer'))
2022-12-09 20:44:37,597 ERROR   Thread-11 :3275 [internal_api.py:upload_file():1614] upload_file request headers: {'User-Agent': 'python-requests/2.27.1', 'Accept-Encoding': 'gzip, deflate', 'Accept': '*/*', 'Connection': 'keep-alive', 'Content-Length': '854'}
2022-12-09 20:44:37,597 ERROR   Thread-11 :3275 [internal_api.py:upload_file():1616] upload_file response body: 
2022-12-09 20:44:43,553 ERROR   Thread-13 :3275 [internal_api.py:upload_file():1612] upload_file exception https://storage.googleapis.com/wandb-production.appspot.com/livion/GridWorld/po5cuaz3/diff.patch?Expires=1670675093&GoogleAccessId=wandb-production%40appspot.gserviceaccount.com&Signature=ir3Y4stRUyjhJf3sq8Alayogz15KvLnBSX1%2BBiiq0QdxXqONLdU6NQMFuBLaMakTaVFUc0WBVpTmbYP65VEQ8We89gKeGdCRtpU9j6AtZZ1IRvT%2BlSgK2vNzFa4Jk81FkmNq419QS0nLBpAuGXarXYXlq2xVL3NbQqxD2CaQJVxSFlEJmC3B4AZmOfFOZv9%2FnQ0%2B%2FwRDxYsVPODEuDD6uHxsu0OkqROb25EjOT7Sy4A%2Bi8ecrShs3a6%2FxaGPWhyHS618XPaW8vtLHm5DrsjeW51wflvt6EYAcqBhmVv7oOnQr3tPLw1OoYvIYxI5sJY0wlqe18TcdcLcJUbLZCT0SQ%3D%3D: ('Connection aborted.', ConnectionResetError(54, 'Connection reset by peer'))
2022-12-09 20:44:43,554 ERROR   Thread-13 :3275 [internal_api.py:upload_file():1614] upload_file request headers: {'User-Agent': 'python-requests/2.27.1', 'Accept-Encoding': 'gzip, deflate', 'Accept': '*/*', 'Connection': 'keep-alive', 'Content-Length': '3348'}
2022-12-09 20:44:43,554 ERROR   Thread-13 :3275 [internal_api.py:upload_file():1616] upload_file response body: 
2022-12-09 20:49:59,620 ERROR   Thread-11 :3275 [internal_api.py:upload_file():1612] upload_file exception https://storage.googleapis.com/wandb-production.appspot.com/livion/GridWorld/po5cuaz3/wandb-metadata.json?Expires=1670675092&GoogleAccessId=wandb-production%40appspot.gserviceaccount.com&Signature=RW9BzYjp2XBDJrfR6htGS1TPEXJS4bOOFwQsSiOCWiaUHO1SMuy6VxNbSeF8yTeRwBZz6HY9L57daE5tooTpMkIIDFWNH3L7opzPgdWL03tumm3ymi%2FH2UX4%2FVO5%2BFD8N%2FsF7Wmwu3QOVqV%2FtnHKCeXa2gHcHT%2BZgSH17r%2FpOt4%2F1hrCcZEyKsBfIznC%2BNtYr0DNne47BxZCcEY5XqbepU5Sd7RR3gPbZussP5P4QDORBQ1ViboCq9mxZroWYsZbMWdsbnqIEo88YU477sWCbszeC7TLhAiqA6zPW5Ox%2ByyEf2Q71n5B4wcMsMpE8ObULUPJ7y2N3cXIhjz%2BTOPZ5Q%3D%3D: ('Connection aborted.', ConnectionResetError(54, 'Connection reset by peer'))
2022-12-09 20:49:59,638 ERROR   Thread-11 :3275 [internal_api.py:upload_file():1614] upload_file request headers: {'User-Agent': 'python-requests/2.27.1', 'Accept-Encoding': 'gzip, deflate', 'Accept': '*/*', 'Connection': 'keep-alive', 'Content-Length': '854'}
2022-12-09 20:49:59,639 ERROR   Thread-11 :3275 [internal_api.py:upload_file():1616] upload_file response body: 
2022-12-09 20:50:22,352 ERROR   Thread-13 :3275 [internal_api.py:upload_file():1612] upload_file exception https://storage.googleapis.com/wandb-production.appspot.com/livion/GridWorld/po5cuaz3/diff.patch?Expires=1670675093&GoogleAccessId=wandb-production%40appspot.gserviceaccount.com&Signature=ir3Y4stRUyjhJf3sq8Alayogz15KvLnBSX1%2BBiiq0QdxXqONLdU6NQMFuBLaMakTaVFUc0WBVpTmbYP65VEQ8We89gKeGdCRtpU9j6AtZZ1IRvT%2BlSgK2vNzFa4Jk81FkmNq419QS0nLBpAuGXarXYXlq2xVL3NbQqxD2CaQJVxSFlEJmC3B4AZmOfFOZv9%2FnQ0%2B%2FwRDxYsVPODEuDD6uHxsu0OkqROb25EjOT7Sy4A%2Bi8ecrShs3a6%2FxaGPWhyHS618XPaW8vtLHm5DrsjeW51wflvt6EYAcqBhmVv7oOnQr3tPLw1OoYvIYxI5sJY0wlqe18TcdcLcJUbLZCT0SQ%3D%3D: ('Connection aborted.', ConnectionResetError(54, 'Connection reset by peer'))
2022-12-09 20:50:22,352 ERROR   Thread-13 :3275 [internal_api.py:upload_file():1614] upload_file request headers: {'User-Agent': 'python-requests/2.27.1', 'Accept-Encoding': 'gzip, deflate', 'Accept': '*/*', 'Connection': 'keep-alive', 'Content-Length': '3348'}
2022-12-09 20:50:22,352 ERROR   Thread-13 :3275 [internal_api.py:upload_file():1616] upload_file response body: 
2022-12-09 20:55:14,931 ERROR   Thread-11 :3275 [internal_api.py:upload_file():1612] upload_file exception https://storage.googleapis.com/wandb-production.appspot.com/livion/GridWorld/po5cuaz3/wandb-metadata.json?Expires=1670675092&GoogleAccessId=wandb-production%40appspot.gserviceaccount.com&Signature=RW9BzYjp2XBDJrfR6htGS1TPEXJS4bOOFwQsSiOCWiaUHO1SMuy6VxNbSeF8yTeRwBZz6HY9L57daE5tooTpMkIIDFWNH3L7opzPgdWL03tumm3ymi%2FH2UX4%2FVO5%2BFD8N%2FsF7Wmwu3QOVqV%2FtnHKCeXa2gHcHT%2BZgSH17r%2FpOt4%2F1hrCcZEyKsBfIznC%2BNtYr0DNne47BxZCcEY5XqbepU5Sd7RR3gPbZussP5P4QDORBQ1ViboCq9mxZroWYsZbMWdsbnqIEo88YU477sWCbszeC7TLhAiqA6zPW5Ox%2ByyEf2Q71n5B4wcMsMpE8ObULUPJ7y2N3cXIhjz%2BTOPZ5Q%3D%3D: ('Connection aborted.', ConnectionResetError(54, 'Connection reset by peer'))
2022-12-09 20:55:14,931 ERROR   Thread-11 :3275 [internal_api.py:upload_file():1614] upload_file request headers: {'User-Agent': 'python-requests/2.27.1', 'Accept-Encoding': 'gzip, deflate', 'Accept': '*/*', 'Connection': 'keep-alive', 'Content-Length': '854'}
2022-12-09 20:55:14,931 ERROR   Thread-11 :3275 [internal_api.py:upload_file():1616] upload_file response body: 
2022-12-09 20:56:28,349 ERROR   Thread-13 :3275 [internal_api.py:upload_file():1612] upload_file exception https://storage.googleapis.com/wandb-production.appspot.com/livion/GridWorld/po5cuaz3/diff.patch?Expires=1670675093&GoogleAccessId=wandb-production%40appspot.gserviceaccount.com&Signature=ir3Y4stRUyjhJf3sq8Alayogz15KvLnBSX1%2BBiiq0QdxXqONLdU6NQMFuBLaMakTaVFUc0WBVpTmbYP65VEQ8We89gKeGdCRtpU9j6AtZZ1IRvT%2BlSgK2vNzFa4Jk81FkmNq419QS0nLBpAuGXarXYXlq2xVL3NbQqxD2CaQJVxSFlEJmC3B4AZmOfFOZv9%2FnQ0%2B%2FwRDxYsVPODEuDD6uHxsu0OkqROb25EjOT7Sy4A%2Bi8ecrShs3a6%2FxaGPWhyHS618XPaW8vtLHm5DrsjeW51wflvt6EYAcqBhmVv7oOnQr3tPLw1OoYvIYxI5sJY0wlqe18TcdcLcJUbLZCT0SQ%3D%3D: ('Connection aborted.', ConnectionResetError(54, 'Connection reset by peer'))
2022-12-09 20:56:28,349 ERROR   Thread-13 :3275 [internal_api.py:upload_file():1614] upload_file request headers: {'User-Agent': 'python-requests/2.27.1', 'Accept-Encoding': 'gzip, deflate', 'Accept': '*/*', 'Connection': 'keep-alive', 'Content-Length': '3348'}
2022-12-09 20:56:28,349 ERROR   Thread-13 :3275 [internal_api.py:upload_file():1616] upload_file response body: 
2022-12-09 21:00:14,341 WARNING FileStreamThread:3275 [file_stream.py:request_with_retry():594] requests_with_retry encountered retryable exception: HTTPSConnectionPool(host='api.wandb.ai', port=443): Max retries exceeded with url: /files/livion/GridWorld/po5cuaz3/file_stream (Caused by ProxyError('Cannot connect to proxy.', ConnectionResetError(54, 'Connection reset by peer'))). func: <bound method Session.post of <requests.sessions.Session object at 0x7f7fdbf9e430>>, args: ('https://api.wandb.ai/files/livion/GridWorld/po5cuaz3/file_stream',), kwargs: {'json': {'complete': False, 'failed': False, 'dropped': 0, 'uploaded': ['code/PPOagent.py']}}
2022-12-09 21:01:03,061 INFO    Thread-11 :3275 [upload_job.py:push():137] Uploaded file /var/folders/cs/3rd5xjms5qd5nj6fr2n86d380000gn/T/tmpph133j6vwandb/fef12fnf-wandb-metadata.json
2022-12-09 21:01:54,955 INFO    Thread-13 :3275 [upload_job.py:push():137] Uploaded file /var/folders/cs/3rd5xjms5qd5nj6fr2n86d380000gn/T/tmpph133j6vwandb/5aizdvqx-diff.patch
2022-12-09 21:01:56,097 INFO    MainThread:3275 [internal.py:handle_exit():82] Internal process exited
